<mujoco model="piper">
    <compiler angle="radian" assetdir="../" autolimits="true"/>
    <option integrator="RK4"/> <!-- 表示仿真器使用rk4（四阶龙阁库塔积分器）作为数值仿真器 -->
    <!-- <size njmax="500" nconmax="100" />  物理引擎的最大关节数和接触数 -->
    <asset>
        <texture type="skybox" builtin="gradient" rgb1="0.3 0.5 0.7" rgb2="0 0 0" width="512" height="3072"/>
        <texture type="2d" name="groundplane" builtin="checker" mark="edge" rgb1="0.2 0.3 0.4" rgb2="0.1 0.2 0.3"
        markrgb="0.8 0.8 0.8" width="300" height="300"/>
        <texture file="textures/light-wood.png" name="woodplane" type="2d"/>
        <material name="groundplane" texture="woodplane" texuniform="true" texrepeat="5 5" reflectance="0.2"/>
        <mesh name="base_link" file="meshes/base_link.STL" />
        <mesh name="link1" file="meshes_mujoco/link1.STL" />
        <mesh name="link2" file="meshes_mujoco/link2.STL" />
        <mesh name="link3" file="meshes_mujoco/link3.STL" />
        <mesh name="link4" file="meshes_mujoco/link4.STL" />
        <mesh name="link5" file="meshes_mujoco/link5.STL" />
        <mesh name="link6" file="meshes_mujoco/link6.STL" />
        <mesh name="link7" file="meshes_mujoco/link7.STL" />
        <mesh name="link8" file="meshes_mujoco/link8.STL" />
        <material name="my_color" rgba="1 0 0 1"/>
        <material name="car_body_material" rgba="0.8 0.8 0.8 1" reflectance="0.7" shininess="0.9"/>
    </asset>
        <default>
        <joint damping="1"/> <!-- 关节的默认阻尼值 -->
    </default>
    <worldbody>
        <light pos="0 0 10" dir="0 0 -1" directional="true" diffuse="0.7 0.7 0.7" castshadow="true"/>
        <geom name="floor" size="0 0 0.05" type="plane" material="groundplane"/>
        <body name="piper_link1" pos="0.275 0 0.245701" quat="0.707105 0 0 -0.707108">
            <inertial pos="0.00131676 0.000310289 -0.00922875" quat="0.557105 0.432155 0.377373 0.600388" mass="0.0001" diaginertia="9.25942e-05 8.3083e-05 7.69469e-05" />
            <joint name="piper_joint1" pos="0 0 0" axis="0 0 1" limited="true" range="-2.618 2.618" />
            <geom type="mesh" rgba="0.792157 0.819608 0.933333 1" mesh="link1" />
            <body name="piper_link2" pos="0 0 0" quat="0.524588 0.474136 -0.524592 -0.474136">
                <inertial pos="0.147616 -0.017426 0.00175953" quat="0.0107531 0.706346 -0.0276284 0.707246" mass="0.0001" diaginertia="0.00177449 0.0017305 0.000145443" />
                <joint name="piper_joint2" pos="0 0 0" axis="0 0 1" limited="true" range="0 3.14" />
                <geom type="mesh" rgba="0.792157 0.819608 0.933333 1" mesh="link2" />
                <body name="piper_link3" pos="0.28503 0 0" quat="0.770418 0 0 0.637539">
                    <inertial pos="0.0156727 0.104467 0.000508487" quat="0.506574 0.477898 -0.524055 0.490268" mass="0.0001" diaginertia="0.000241862 0.000222142 0.000100381" />
                    <joint name="piper_joint3" pos="0 0 0" axis="0 0 1" limited="true" range="-2.697 0" />
                    <geom type="mesh" rgba="0.792157 0.819608 0.933333 1" mesh="link3" />
                    <body name="piper_link4" pos="0.021984 0.25075 0" quat="0.707105 -0.707108 0 0">
                        <inertial pos="0.000276465 -0.00102804 -0.00472831" quat="0.492305 0.505285 0.503294 0.499017" mass="0.0001" diaginertia="4.87057e-05 4.10595e-05 3.82001e-05" />
                        <joint name="piper_joint4" pos="0 0 0" axis="0 0 1" limited="true" range="-1.832 1.832" />
                        <geom type="mesh" rgba="0.792157 0.819608 0.933333 1" mesh="link4" />
                        <body name="piper_link5" pos="0 0 0" quat="0.707105 0.707108 0 0">
                            <inertial pos="8.82262e-05 0.0566829 -0.0019612" quat="0.507447 0.490986 0.506887 0.494466" mass="0.0001" diaginertia="5.63237e-05 4.88652e-05 4.39642e-05" />
                            <joint name="piper_joint5" pos="0 0 0" axis="0 0 1" limited="true" range="-1.22 1.22" />
                            <geom type="mesh" rgba="0.792157 0.819608 0.933333 1" mesh="link5" />
                            <body name="piper_link6" pos="0 0.091 0.0014165" quat="0.499998 -0.5 -0.5 -0.500002">
                                <inertial pos="1.16933e-08 0.000341211 0.0342123" quat="0.00199303 0.707103 0.0022686 0.707104" mass="0.0001" diaginertia="0.000118283 9.9975e-05 4.31751e-05" />
                                <joint name="piper_joint6" pos="0 0 0" axis="0 0 1" limited="true" range="-3.14 3.14" />
                                <geom type="mesh" rgba="0.792157 0.819608 0.933333 1" mesh="link6" />
                            </body>
                        </body>
                    </body>
                </body>
            </body>
        </body>
    </worldbody>
    <actuator>
    <!-- xarm actuators -->
    <motor name="arm_actuator_1" joint="piper_joint1" ctrlrange="-100 100" />
    <motor name="arm_actuator_2" joint="piper_joint2" ctrlrange="-100 100" />
    <motor name="arm_actuator_3" joint="piper_joint3" ctrlrange="-100 100" />
    <motor name="arm_actuator_4" joint="piper_joint4" ctrlrange="-100 100" />
    <motor name="arm_actuator_5" joint="piper_joint5" ctrlrange="-100 100" />
    <motor name="arm_actuator_6" joint="piper_joint6" ctrlrange="-100 100" />
    </actuator>
</mujoco>
